Workbook

Sheet 投保清单（请在此清单中填写）
B2: 点此阅读：（人身）保险入门（不完全）指南 | L2: 家庭保单管理表
B5: 被保人 | C5: 产品类型 | D5: 保险公司 | E5: 保险名称 | F5: 保单号码 | G5: 主险保额 （万） | H5: 保费 （元） | I5: 缴费日期 | J5: 生效日期 | K5: 等待期 | L5: 保障期间 | M5: 缴费期 | N5: 缴费方式 | O5: 缴费银行卡 | P5: 投保人 | Q5: 受益人 | R5: 理赔电话 | S5: 保险责任
B6: 保障谁 | C6: 保什么 | D6: 哪家公司买的 | E6: 买的啥 | F6: 保单号 | G6: 保多少 | H6: 交多少钱 | I6: 啥时候交钱 | J6: 何时生效 | K6: 投保后多少天不保 | L6: 保多久 | M6: 钱交多久 | N6: 怎么交 | O6: 哪张卡 | P6: 谁交钱 | Q6: 钱赔给谁 | R6: 出事了找谁 | S6: 具体保障啥
B7: 老公 | C7: 重疾险 | D7: 光大永明人寿 | E7: 光大嘉多保重大疾病保险 | F7: 123456789 | G7: 50 | H7: 8585 | I7: 43628 | J7: 43629 | K7: 90 | L7: 终身 | M7: 30年 | N7: 年缴 | O7: 中行0607 | P7: 老婆 | Q7: 法定 | R7: 95348 | S7: 110种重疾，分6组，最多赔6次保额，投保前10年额外赔20%（出险时年龄小于50岁）； 20种中症，不分组，额外赔50%保额，最多2次； 40种轻症，不分组，额外赔30%、35%、40%保额，最多3次； 身故赔付：身故赔基本保额
C8: 意外险
C9: 寿险
C10: 医疗险
C11: 其他
B15: 被保人 | C15: 产品类型 | D15: 保险公司 | E15: 保险名称 | F15: 保单号码 | G15: 主险保额 （万） | H15: 保费 （元） | I15: 缴费日期 | J15: 生效日期 | K15: 等待期 | L15: 保障期间 | M15: 缴费期 | N15: 缴费方式 | O15: 缴费银行卡 | P15: 投保人 | Q15: 受益人 | R15: 理赔电话 | S15: 保险责任
B16: 保障谁 | C16: 保什么 | D16: 哪家公司买的 | E16: 买的啥 | F16: 保单号 | G16: 保多少 | H16: 交多少钱 | I16: 啥时候交钱 | J16: 何时生效 | K16: 投保后多少天不保 | L16: 保多久 | M16: 钱交多久 | N16: 怎么交 | O16: 哪张卡 | P16: 谁交钱 | Q16: 钱赔给谁 | R16: 出事了找谁 | S16: 具体保障啥
B17: 老婆 | C17: 重疾险
C18: 意外险
C19: 寿险
C20: 医疗险
C21: 其他
B25: 被保人 | C25: 产品类型 | D25: 保险公司 | E25: 保险名称 | F25: 保单号码 | G25: 主险保额 （万） | H25: 保费 （元） | I25: 缴费日期 | J25: 生效日期 | K25: 等待期 | L25: 保障期间 | M25: 缴费期 | N25: 缴费方式 | O25: 缴费银行卡 | P25: 投保人 | Q25: 受益人 | R25: 理赔电话 | S25: 保险责任
B26: 保障谁 | C26: 保什么 | D26: 哪家公司买的 | E26: 买的啥 | F26: 保单号 | G26: 保多少 | H26: 交多少钱 | I26: 啥时候交钱 | J26: 何时生效 | K26: 投保后多少天不保 | L26: 保多久 | M26: 钱交多久 | N26: 怎么交 | O26: 哪张卡 | P26: 谁交钱 | Q26: 钱赔给谁 | R26: 出事了找谁 | S26: 具体保障啥
B27: 女儿 | C27: 重疾险
C28: 意外险
C29: 医疗险
C30: 其他
B35: 被保人 | C35: 产品类型 | D35: 保险公司 | E35: 保险名称 | F35: 保单号码 | G35: 主险保额 （万） | H35: 保费 （元） | I35: 缴费日期 | J35: 生效日期 | K35: 等待期 | L35: 保障期间 | M35: 缴费期 | N35: 缴费方式 | O35: 缴费银行卡 | P35: 投保人 | Q35: 受益人 | R35: 理赔电话 | S35: 保险责任
B36: 保障谁 | C36: 保什么 | D36: 哪家公司买的 | E36: 买的啥 | F36: 保单号 | G36: 保多少 | H36: 交多少钱 | I36: 啥时候交钱 | J36: 何时生效 | K36: 投保后多少天不保 | L36: 保多久 | M36: 钱交多久 | N36: 怎么交 | O36: 哪张卡 | P36: 谁交钱 | Q36: 钱赔给谁 | R36: 出事了找谁 | S36: 具体保障啥
B37: 儿子 | C37: 重疾险
C38: 意外险
C39: 寿险
C40: 医疗险
C41: 其他
B45: 被保人 | C45: 产品类型 | D45: 保险公司 | E45: 保险名称 | F45: 保单号码 | G45: 主险保额 （万） | H45: 保费 （元） | I45: 缴费日期 | J45: 生效日期 | K45: 等待期 | L45: 保障期间 | M45: 缴费期 | N45: 缴费方式 | O45: 缴费银行卡 | P45: 投保人 | Q45: 受益人 | R45: 理赔电话 | S45: 保险责任
B46: 保障谁 | C46: 保什么 | D46: 哪家公司买的 | E46: 买的啥 | F46: 保单号 | G46: 保多少 | H46: 交多少钱 | I46: 啥时候交钱 | J46: 何时生效 | K46: 投保后多少天不保 | L46: 保多久 | M46: 钱交多久 | N46: 怎么交 | O46: 哪张卡 | P46: 谁交钱 | Q46: 钱赔给谁 | R46: 出事了找谁 | S46: 具体保障啥
B47: 父亲 | C47: 防癌险
C48: 意外险
C49: 医疗险
C50: 其他
B55: 被保人 | C55: 产品类型 | D55: 保险公司 | E55: 保险名称 | F55: 保单号码 | G55: 主险保额 （万） | H55: 保费 （元） | I55: 缴费日期 | J55: 生效日期 | K55: 等待期 | L55: 保障期间 | M55: 缴费期 | N55: 缴费方式 | O55: 缴费银行卡 | P55: 投保人 | Q55: 受益人 | R55: 理赔电话 | S55: 保险责任
B56: 保障谁 | C56: 保什么 | D56: 哪家公司买的 | E56: 买的啥 | F56: 保单号 | G56: 保多少 | H56: 交多少钱 | I56: 啥时候交钱 | J56: 何时生效 | K56: 投保后多少天不保 | L56: 保多久 | M56: 钱交多久 | N56: 怎么交 | O56: 哪张卡 | P56: 谁交钱 | Q56: 钱赔给谁 | R56: 出事了找谁 | S56: 具体保障啥
B57: 母亲 | C57: 重疾险
C58: 意外险
C59: 医疗险
C60: 其他
...

Sheet 汇总表格（无需手动填写）
B2: 当前日期 | C2: =NOW() -> 44509.951
B3: 家庭成员保额及缴费汇总表
B4: 成员 | C4: 重疾险 | D4: 意外险 | E4: 寿险 | F4: 医疗险 | G4: 其他 | H4: 总保额 （万） | I4: 每年缴费 （元）
B5: 老公 | C5: =SUMIF('投保清单（请在此清单中填写）'!$C$7:$C$13,'汇总表格（无需手动填写）'!C4,'投保清单（请在此清单中填写）'!$G$7:$G$13) -> 50 | D5: =SUMIF('投保清单（请在此清单中填写）'!$C$7:$C$13,'汇总表格（无需手动填写）'!D4,'投保清单（请在此清单中填写）'!$G$7:$G$13) -> 0 | E5: =SUMIF('投保清单（请在此清单中填写）'!$C$7:$C$13,'汇总表格（无需手动填写）'!E4,'投保清单（请在此清单中填写）'!$G$7:$G$13) -> 0 | F5: =SUMIF('投保清单（请在此清单中填写）'!$C$7:$C$13,'汇总表格（无需手动填写）'!F4,'投保清单（请在此清单中填写）'!$G$7:$G$13) -> 0 | G5: =SUMIF('投保清单（请在此清单中填写）'!$C$7:$C$13,'汇总表格（无需手动填写）'!G4,'投保清单（请在此清单中填写）'!$G$7:$G$13) -> 0 | H5: =SUM(C5:G5) -> 50 | I5: =SUM('投保清单（请在此清单中填写）'!H7:H13) -> 8585
B6: 老婆 | C6: =SUMIF('投保清单（请在此清单中填写）'!$C$17:$C$23,'汇总表格（无需手动填写）'!C4,'投保清单（请在此清单中填写）'!$G$17:$G$23) -> 0 | D6: =SUMIF('投保清单（请在此清单中填写）'!$C$17:$C$23,'汇总表格（无需手动填写）'!D4,'投保清单（请在此清单中填写）'!$G$17:$G$23) -> 0 | E6: =SUMIF('投保清单（请在此清单中填写）'!$C$17:$C$23,'汇总表格（无需手动填写）'!E4,'投保清单（请在此清单中填写）'!$G$17:$G$23) -> 0 | F6: =SUMIF('投保清单（请在此清单中填写）'!$C$17:$C$23,'汇总表格（无需手动填写）'!F4,'投保清单（请在此清单中填写）'!$G$17:$G$23) -> 0 | G6: =SUMIF('投保清单（请在此清单中填写）'!$C$17:$C$23,'汇总表格（无需手动填写）'!G4,'投保清单（请在此清单中填写）'!$G$17:$G$23) -> 0 | H6: =SUM(C6:G6) -> 0 | I6: =SUM('投保清单（请在此清单中填写）'!H17:H23) -> 0
B7: 女儿 | C7: =SUMIF('投保清单（请在此清单中填写）'!$C$27:$C$33,'汇总表格（无需手动填写）'!C4,'投保清单（请在此清单中填写）'!$G$27:$G$33) -> 0 | D7: =SUMIF('投保清单（请在此清单中填写）'!$C$27:$C$33,'汇总表格（无需手动填写）'!D4,'投保清单（请在此清单中填写）'!$G$27:$G$33) -> 0 | E7: =SUMIF('投保清单（请在此清单中填写）'!$C$27:$C$33,'汇总表格（无需手动填写）'!E4,'投保清单（请在此清单中填写）'!$G$27:$G$33) -> 0 | F7: =SUMIF('投保清单（请在此清单中填写）'!$C$27:$C$33,'汇总表格（无需手动填写）'!F4,'投保清单（请在此清单中填写）'!$G$27:$G$33) -> 0 | G7: =SUMIF('投保清单（请在此清单中填写）'!$C$27:$C$33,'汇总表格（无需手动填写）'!G4,'投保清单（请在此清单中填写）'!$G$27:$G$33) -> 0 | H7: =SUM(C7:G7) -> 0 | I7: =SUM('投保清单（请在此清单中填写）'!H27:H33) -> 0
B8: 儿子 | C8: =SUMIF('投保清单（请在此清单中填写）'!$C$37:$C$43,'汇总表格（无需手动填写）'!C4,'投保清单（请在此清单中填写）'!$G$37:$G$43) -> 0 | D8: =SUMIF('投保清单（请在此清单中填写）'!$C$37:$C$43,'汇总表格（无需手动填写）'!D4,'投保清单（请在此清单中填写）'!$G$37:$G$43) -> 0 | E8: =SUMIF('投保清单（请在此清单中填写）'!$C$37:$C$43,'汇总表格（无需手动填写）'!E4,'投保清单（请在此清单中填写）'!$G$37:$G$43) -> 0 | F8: =SUMIF('投保清单（请在此清单中填写）'!$C$37:$C$43,'汇总表格（无需手动填写）'!F4,'投保清单（请在此清单中填写）'!$G$37:$G$43) -> 0 | G8: =SUMIF('投保清单（请在此清单中填写）'!$C$37:$C$43,'汇总表格（无需手动填写）'!G4,'投保清单（请在此清单中填写）'!$G$37:$G$43) -> 0 | H8: =SUM(C8:G8) -> 0 | I8: =SUM('投保清单（请在此清单中填写）'!H37:H43) -> 0
B9: 父亲 | C9: =SUMIF('投保清单（请在此清单中填写）'!$C$47:$C$53,'汇总表格（无需手动填写）'!C4,'投保清单（请在此清单中填写）'!$G$47:$G$53) -> 0 | D9: =SUMIF('投保清单（请在此清单中填写）'!$C$47:$C$53,'汇总表格（无需手动填写）'!D4,'投保清单（请在此清单中填写）'!$G$47:$G$53) -> 0 | E9: =SUMIF('投保清单（请在此清单中填写）'!$C$47:$C$53,'汇总表格（无需手动填写）'!E4,'投保清单（请在此清单中填写）'!$G$47:$G$53) -> 0 | F9: =SUMIF('投保清单（请在此清单中填写）'!$C$47:$C$53,'汇总表格（无需手动填写）'!F4,'投保清单（请在此清单中填写）'!$G$47:$G$53) -> 0 | G9: =SUMIF('投保清单（请在此清单中填写）'!$C$47:$C$53,'汇总表格（无需手动填写）'!G4,'投保清单（请在此清单中填写）'!$G$47:$G$53) -> 0 | H9: =SUM(C9:G9) -> 0 | I9: =SUM('投保清单（请在此清单中填写）'!H47:H53) -> 0
B10: 母亲 | C10: =SUMIF('投保清单（请在此清单中填写）'!$C$57:$C$63,'汇总表格（无需手动填写）'!C4,'投保清单（请在此清单中填写）'!$G$57:$G$63) -> 0 | D10: =SUMIF('投保清单（请在此清单中填写）'!$C$57:$C$63,'汇总表格（无需手动填写）'!D4,'投保清单（请在此清单中填写）'!$G$57:$G$63) -> 0 | E10: =SUMIF('投保清单（请在此清单中填写）'!$C$57:$C$63,'汇总表格（无需手动填写）'!E4,'投保清单（请在此清单中填写）'!$G$57:$G$63) -> 0 | F10: =SUMIF('投保清单（请在此清单中填写）'!$C$57:$C$63,'汇总表格（无需手动填写）'!F4,'投保清单（请在此清单中填写）'!$G$57:$G$63) -> 0 | G10: =SUMIF('投保清单（请在此清单中填写）'!$C$57:$C$63,'汇总表格（无需手动填写）'!G4,'投保清单（请在此清单中填写）'!$G$57:$G$63) -> 0 | H10: =SUM(C10:G10) -> 0 | I10: =SUM('投保清单（请在此清单中填写）'!H57:H63) -> 0
B11: 其他1 | C11: =SUMIF('投保清单（请在此清单中填写）'!$C$67:$C$73,'汇总表格（无需手动填写）'!C4,'投保清单（请在此清单中填写）'!$G$67:$G$73) -> 0 | D11: =SUMIF('投保清单（请在此清单中填写）'!$C$67:$C$73,'汇总表格（无需手动填写）'!D4,'投保清单（请在此清单中填写）'!$G$67:$G$73) -> 0 | E11: =SUMIF('投保清单（请在此清单中填写）'!$C$67:$C$73,'汇总表格（无需手动填写）'!E4,'投保清单（请在此清单中填写）'!$G$67:$G$73) -> 0 | F11: =SUMIF('投保清单（请在此清单中填写）'!$C$67:$C$73,'汇总表格（无需手动填写）'!F4,'投保清单（请在此清单中填写）'!$G$67:$G$73) -> 0 | G11: =SUMIF('投保清单（请在此清单中填写）'!$C$67:$C$73,'汇总表格（无需手动填写）'!G4,'投保清单（请在此清单中填写）'!$G$67:$G$73) -> 0 | H11: =SUM(C11:G11) -> 0 | I11: =SUM('投保清单（请在此清单中填写）'!H67:H73) -> 0
B12: 其他2 | C12: =SUMIF('投保清单（请在此清单中填写）'!$C$77:$C$83,'汇总表格（无需手动填写）'!C4,'投保清单（请在此清单中填写）'!$G$77:$G$83) -> 0 | D12: =SUMIF('投保清单（请在此清单中填写）'!$C$77:$C$83,'汇总表格（无需手动填写）'!D4,'投保清单（请在此清单中填写）'!$G$77:$G$83) -> 0 | E12: =SUMIF('投保清单（请在此清单中填写）'!$C$77:$C$83,'汇总表格（无需手动填写）'!E4,'投保清单（请在此清单中填写）'!$G$77:$G$83) -> 0 | F12: =SUMIF('投保清单（请在此清单中填写）'!$C$77:$C$83,'汇总表格（无需手动填写）'!F4,'投保清单（请在此清单中填写）'!$G$77:$G$83) -> 0 | G12: =SUMIF('投保清单（请在此清单中填写）'!$C$77:$C$83,'汇总表格（无需手动填写）'!G4,'投保清单（请在此清单中填写）'!$G$77:$G$83) -> 0 | H12: =SUM(C12:G12) -> 0 | I12: =SUM('投保清单（请在此清单中填写）'!H77:H83) -> 0
B13: 其他3 | C13: =SUMIF('投保清单（请在此清单中填写）'!$C$87:$C$93,'汇总表格（无需手动填写）'!C4,'投保清单（请在此清单中填写）'!$G$87:$G$93) -> 0 | D13: =SUMIF('投保清单（请在此清单中填写）'!$C$87:$C$93,'汇总表格（无需手动填写）'!D4,'投保清单（请在此清单中填写）'!$G$87:$G$93) -> 0 | E13: =SUMIF('投保清单（请在此清单中填写）'!$C$87:$C$93,'汇总表格（无需手动填写）'!E4,'投保清单（请在此清单中填写）'!$G$87:$G$93) -> 0 | F13: =SUMIF('投保清单（请在此清单中填写）'!$C$87:$C$93,'汇总表格（无需手动填写）'!F4,'投保清单（请在此清单中填写）'!$G$87:$G$93) -> 0 | G13: =SUMIF('投保清单（请在此清单中填写）'!$C$87:$C$93,'汇总表格（无需手动填写）'!G4,'投保清单（请在此清单中填写）'!$G$87:$G$93) -> 0 | H13: =SUM(C13:G13) -> 0 | I13: =SUM('投保清单（请在此清单中填写）'!H87:H93) -> 0
B14: 其他4 | C14: =SUMIF('投保清单（请在此清单中填写）'!$C$97:$C$103,'汇总表格（无需手动填写）'!C4,'投保清单（请在此清单中填写）'!$G$97:$G$103) -> 0 | D14: =SUMIF('投保清单（请在此清单中填写）'!$C$97:$C$103,'汇总表格（无需手动填写）'!D4,'投保清单（请在此清单中填写）'!$G$97:$G$103) -> 0 | E14: =SUMIF('投保清单（请在此清单中填写）'!$C$97:$C$103,'汇总表格（无需手动填写）'!E4,'投保清单（请在此清单中填写）'!$G$97:$G$103) -> 0 | F14: =SUMIF('投保清单（请在此清单中填写）'!$C$97:$C$103,'汇总表格（无需手动填写）'!F4,'投保清单（请在此清单中填写）'!$G$97:$G$103) -> 0 | G14: =SUMIF('投保清单（请在此清单中填写）'!$C$97:$C$103,'汇总表格（无需手动填写）'!G4,'投保清单（请在此清单中填写）'!$G$97:$G$103) -> 0 | H14: =SUM(C14:G14) -> 0 | I14: =SUM('投保清单（请在此清单中填写）'!H97:H103) -> 0
B15: 合计（万） | C15: =SUM(C5:C14) -> 50 | D15: =SUM(D5:D14) -> 0 | E15: =SUM(E5:E14) -> 0 | F15: =SUM(F5:F14) -> 0 | G15: =SUM(G5:G14) -> 0 | H15: =SUM(H5:H14) -> 50 | I15: =SUM(I5:I14) -> 8585

Sheet 附表-常见保险公司客服热线
A1: 常见保险公司客服热线 （按首字母顺序排列）
A2: 序号 | B2: 保险公司 | C2: 客服热线
A3: 1 | B3: 安邦人寿/大家人寿 | C3: 95569
A4: 2 | B4: 安联保险 | C4: 400-800-2020
A5: 3 | B5: 安盛天平保险 | C5: 95550
A6: 4 | B6: 安心保险 | C6: 95303
A7: 5 | B7: 百年人寿 | C7: 95542
A8: 6 | B8: 渤海人寿 | C8: 4008-667-668
A9: 7 | B9: 大地保险 | C9: 95590
A10: 8 | B10: 德华安顾人寿 | C10: 400-888-0011
A11: 9 | B11: 复星保德信 | C11: 400-821-6808
A12: 10 | B12: 复星联合健康 | C12: 4006-11-7777
A13: 11 | B13: 光大永明人寿 | C13: 95348
A14: 12 | B14: 国富人寿 | C14: 0771-5723168
A15: 13 | B15: 国华人寿 | C15: 95549
A16: 14 | B16: 国任保险 | C16: 4008-667788
A17: 15 | B17: 国泰产险 | C17: 400-820-2288
A18: 16 | B18: 海保人寿 | C18: 400-898-0899
A19: 17 | B19: 和谐健康保险 | C19: 95569-5
A20: 18 | B20: 弘康人寿 | C20: 4008-500-365
A21: 19 | B21: 华贵人寿 | C21: 400-684-1888
A22: 20 | B22: 华泰保险 | C22: 400-609-5509
A23: 21 | B23: 昆仑健康保险 | C23: 400-811-8899
A24: 22 | B24: 美亚保险 | C24: 400-820-8858
A25: 23 | B25: 平安保险 | C25: 95511
A26: 24 | B26: 瑞华健康保险 | C26: 400-609-6868
A27: 25 | B27: 瑞泰人寿 | C27: 400-810-9339
A28: 26 | B28: 三峡人寿 | C28: 023 96999
A29: 27 | B29: 上海人寿 | C29: 4009118118
A30: 28 | B30: 史带财险 | C30: 40099 95507
A31: 29 | B31: 太平保险 | C31: 95589
A32: 30 | B32: 太平洋保险 | C32: 95500
A33: 31 | B33: 泰康在线 | C33: 95522
A34: 32 | B34: 天安财险 | C34: 95505
A35: 33 | B35: 信美相互 | C35: 400-139-9990
A36: 34 | B36: 信泰人寿 | C36: 95365
A37: 35 | B37: 亚太财险 | C37: 95506
A38: 36 | B38: 阳光人寿 | C38: 95510
A39: 37 | B39: 易安保险 | C39: 4000-121212
A40: 38 | B40: 长生人寿 | C40: 400-820-8599
...
